Workbook

Sheet Review
A1: Scope & automation review — human decision worksheet (203 test cases)
A2: Fill ONLY the yellow MY_ columns (H, I, L, M). Pick Yes/No from the dropdown. Write a reason whenever you pick No (an orange cell means a reason is missing). Red = your answer differs from the AI suggestion. Purple = out of scope but marked for automation. Agreed? fills in once both of your Yes/No cells are set. Decision criteria and a filled-in example row: see the Guidance sheet. The AI_ columns are copied from test_design.csv, which this workbook does not change.
A3: Test case | F3: AI suggestion — scope | H3: YOUR decision — scope | J3: AI suggestion — automation | L3: YOUR decision — automation | N3: Check
A4: TC_ID | B4: Sub_Module | C4: Title | D4: Type | E4: Priority | F4: AI_suggested_valid_in_scope | G4: AI_reason | H4: MY_valid_in_scope | I4: MY_scope_reason | J4: AI_suggested_needs_automation | K4: AI_reason | L4: MY_needs_automation | M4: MY_automation_reason | N4: Agreed?
A5: TC_ADM_NAV_001 | B5: Login | C5: Successful login routes to Dashboard | D5: Functional | E5: P0 | F5: Yes | J5: Yes | N5: =IF(OR(H5="",L5=""),"",IF(AND(H5=F5,L5=J5),"Yes","No"))
A6: TC_ADM_NAV_002 | B6: Login | C6: Invalid credentials rejected without leaking which field is wrong (Admin/wrongPass) | D6: Negative | E6: P0 | F6: Yes | J6: Yes | N6: =IF(OR(H6="",L6=""),"",IF(AND(H6=F6,L6=J6),"Yes","No"))
A7: TC_ADM_NAV_003 | B7: Login | C7: Invalid credentials rejected without leaking which field is wrong (ghost/admin123) | D7: Negative | E7: P0 | F7: Yes | J7: Yes | K7: Parameter variant of TC_ADM_NAV_002: credentials ghost/admin123. Same page object/component; implemented as an added test in tests/admin/nav.spec.ts, not new code. (Promoted W2 -> W1: test_design_coverage.md §8 rule — every P0 case is Wave 1.) | N7: =IF(OR(H7="",L7=""),"",IF(AND(H7=F7,L7=J7),"Yes","No"))
A8: TC_ADM_NAV_004 | B8: Login | C8: Invalid credentials rejected without leaking which field is wrong (ADMIN/admin123) — KNOWN DEFECT: BUG-003 | D8: Negative | E8: P0 | F8: Yes | J8: Yes | K8: Known-defect guard for BUG-003 (case-insensitive username login) — same page object as TC_ADM_NAV_002, asserting the opposite (actual) outcome. Implemented in tests/admin/nav.spec.ts. (Promoted W2 -> W1: test_design_coverage.md §8 rule — every P0 case is Wave 1.) | N8: =IF(OR(H8="",L8=""),"",IF(AND(H8=F8,L8=J8),"Yes","No"))
A9: TC_ADM_NAV_005 | B9: Login | C9: Required-field validation — Username left empty | D9: Validation | E9: P1 | F9: Yes | J9: Yes | N9: =IF(OR(H9="",L9=""),"",IF(AND(H9=F9,L9=J9),"Yes","No"))
A10: TC_ADM_NAV_006 | B10: Login | C10: Required-field validation — Password left empty | D10: Validation | E10: P1 | F10: Yes | J10: Yes | K10: Wave 2 — parameter variant of TC_ADM_NAV_005: Password field left empty. Same page object/component; implement as an added data row, not new code. | N10: =IF(OR(H10="",L10=""),"",IF(AND(H10=F10,L10=J10),"Yes","No"))
A11: TC_ADM_NAV_007 | B11: Login | C11: Deep link while unauthenticated redirects to login | D11: Negative | E11: P0 | F11: Yes | J11: Yes | N11: =IF(OR(H11="",L11=""),"",IF(AND(H11=F11,L11=J11),"Yes","No"))
A12: TC_ADM_NAV_008 | B12: Admin sidebar | C12: Admin top-tab "User Management" navigates to "System Users" | D12: Navigation | E12: P2 | F12: Yes | J12: Yes | N12: =IF(OR(H12="",L12=""),"",IF(AND(H12=F12,L12=J12),"Yes","No"))
A13: TC_ADM_NAV_009 | B13: Admin sidebar | C13: Admin top-tab "Job" navigates to "Job Titles" | D13: Navigation | E13: P2 | F13: Yes | J13: Yes | K13: Wave 2 — parameter variant of TC_ADM_NAV_008: Job tab -> Job Titles. Same page object/component; implement as an added data row, not new code. | N13: =IF(OR(H13="",L13=""),"",IF(AND(H13=F13,L13=J13),"Yes","No"))
A14: TC_ADM_NAV_010 | B14: Admin sidebar | C14: Admin top-tab "Organization" navigates to "General Information" | D14: Navigation | E14: P2 | F14: Yes | J14: Yes | K14: Wave 2 — parameter variant of TC_ADM_NAV_008: Organization tab -> General Information. Same page object/component; implement as an added data row, not new code. | N14: =IF(OR(H14="",L14=""),"",IF(AND(H14=F14,L14=J14),"Yes","No"))
A15: TC_ADM_NAV_011 | B15: Admin sidebar | C15: Admin top-tab "Qualifications" navigates to "Skills" | D15: Navigation | E15: P2 | F15: Yes | J15: Yes | K15: Wave 2 — parameter variant of TC_ADM_NAV_008: Qualifications tab -> Skills. Same page object/component; implement as an added data row, not new code. | N15: =IF(OR(H15="",L15=""),"",IF(AND(H15=F15,L15=J15),"Yes","No"))
A16: TC_ADM_NAV_012 | B16: Admin sidebar | C16: Admin top-tab "Nationalities" navigates to "Nationalities" | D16: Navigation | E16: P2 | F16: Yes | J16: Yes | K16: Wave 2 — parameter variant of TC_ADM_NAV_008: Nationalities tab -> Nationalities. Same page object/component; implement as an added data row, not new code. | N16: =IF(OR(H16="",L16=""),"",IF(AND(H16=F16,L16=J16),"Yes","No"))
A17: TC_ADM_NAV_013 | B17: Admin sidebar | C17: Admin top-tab "Corporate Branding" navigates to "Corporate Branding" | D17: Navigation | E17: P2 | F17: Yes | J17: Yes | K17: Wave 2 — parameter variant of TC_ADM_NAV_008: Corporate Branding tab -> Corporate Branding. Same page object/component; implement as an added data row, not new code. | N17: =IF(OR(H17="",L17=""),"",IF(AND(H17=F17,L17=J17),"Yes","No"))
A18: TC_ADM_NAV_014 | B18: Admin sidebar | C18: Admin top-tab "Configuration" navigates to "Email Configuration" | D18: Navigation | E18: P2 | F18: Yes | J18: Yes | K18: Wave 2 — parameter variant of TC_ADM_NAV_008: Configuration tab -> Email Configuration. Same page object/component; implement as an added data row, not new code. | N18: =IF(OR(H18="",L18=""),"",IF(AND(H18=F18,L18=J18),"Yes","No"))
A19: TC_ADM_NAV_015 | B19: Session | C19: Logout invalidates the session | D19: Functional | E19: P0 | F19: Yes | J19: Yes | N19: =IF(OR(H19="",L19=""),"",IF(AND(H19=F19,L19=J19),"Yes","No"))
A20: TC_ADM_NAV_016 | B20: Session | C20: Back-navigation after logout does not expose authenticated screens | D20: Negative | E20: P0 | F20: Yes | J20: Yes | N20: =IF(OR(H20="",L20=""),"",IF(AND(H20=F20,L20=J20),"Yes","No"))
A21: TC_ADM_USR_001 | B21: User Management > Users | C21: Add a valid ESS user | D21: Functional | E21: P0 | F21: Yes | J21: Yes | N21: =IF(OR(H21="",L21=""),"",IF(AND(H21=F21,L21=J21),"Yes","No"))
A22: TC_ADM_USR_002 | B22: User Management > Users | C22: Username uniqueness is enforced | D22: Negative | E22: P0 | F22: Yes | J22: Yes | N22: =IF(OR(H22="",L22=""),"",IF(AND(H22=F22,L22=J22),"Yes","No"))
A23: TC_ADM_USR_003 | B23: User Management > Users | C23: Mandatory field blocks submission — User Role empty | D23: Validation | E23: P0 | F23: Yes | J23: Yes | N23: =IF(OR(H23="",L23=""),"",IF(AND(H23=F23,L23=J23),"Yes","No"))
A24: TC_ADM_USR_004 | B24: User Management > Users | C24: Mandatory field blocks submission — Employee Name empty | D24: Validation | E24: P1 | F24: Yes | J24: Yes | K24: Wave 2 — parameter variant of TC_ADM_USR_003: Employee Name left empty. Same page object/component; implement as an added data row, not new code. | N24: =IF(OR(H24="",L24=""),"",IF(AND(H24=F24,L24=J24),"Yes","No"))
A25: TC_ADM_USR_005 | B25: User Management > Users | C25: Mandatory field blocks submission — Status empty | D25: Validation | E25: P0 | F25: Yes | J25: Yes | K25: Parameter variant of TC_ADM_USR_003: Status left empty. Same page object/component (submitAddFormWithEmptyField, already typed for this field); implemented as an added test in tests/admin/usr.spec.ts, not new code. (Promoted W2 -> W1: test_design_coverage.md §8 rule — every P0 case is Wave 1.) | N25: =IF(OR(H25="",L25=""),"",IF(AND(H25=F25,L25=J25),"Yes","No"))
A26: TC_ADM_USR_006 | B26: User Management > Users | C26: Mandatory field blocks submission — Username empty | D26: Validation | E26: P0 | F26: Yes | J26: Yes | K26: Parameter variant of TC_ADM_USR_003: Username left empty. Same page object/component (submitAddFormWithEmptyField, already typed for this field); implemented as an added test in tests/admin/usr.spec.ts, not new code. (Promoted W2 -> W1: test_design_coverage.md §8 rule — every P0 case is Wave 1.) | N26: =IF(OR(H26="",L26=""),"",IF(AND(H26=F26,L26=J26),"Yes","No"))
A27: TC_ADM_USR_007 | B27: User Management > Users | C27: Mandatory field blocks submission — Password empty | D27: Validation | E27: P0 | F27: Yes | J27: Yes | K27: Parameter variant of TC_ADM_USR_003: Password left empty. Same page object/component (submitAddFormWithEmptyField, already typed for this field); implemented as an added test in tests/admin/usr.spec.ts, not new code. (Promoted W2 -> W1: test_design_coverage.md §8 rule — every P0 case is Wave 1.) | N27: =IF(OR(H27="",L27=""),"",IF(AND(H27=F27,L27=J27),"Yes","No"))
A28: TC_ADM_USR_008 | B28: User Management > Users | C28: Employee Name must be chosen from the hint list | D28: Negative | E28: P1 | F28: Yes | J28: Yes | K28: Wave 2 — reuses TC_ADM_USR_001's Employee Name autocomplete helper; adds the "no suggestion selected" negative assertion. Not a pure data variant. | N28: =IF(OR(H28="",L28=""),"",IF(AND(H28=F28,L28=J28),"Yes","No"))
A29: TC_ADM_USR_009 | B29: User Management > Users | C29: Password policy feedback for "abc" | D29: Boundary | E29: P1 | F29: Yes | J29: Yes | N29: =IF(OR(H29="",L29=""),"",IF(AND(H29=F29,L29=J29),"Yes","No"))
A30: TC_ADM_USR_010 | B30: User Management > Users | C30: Password policy feedback for "Password" | D30: Validation | E30: P1 | F30: Yes | J30: Yes | K30: Wave 2 — parameter variant of TC_ADM_USR_009: password "Password". Same page object/component; implement as an added data row, not new code. | N30: =IF(OR(H30="",L30=""),"",IF(AND(H30=F30,L30=J30),"Yes","No"))
A31: TC_ADM_USR_011 | B31: User Management > Users | C31: No upper-case requirement exists on this build | D31: Regression | E31: P2 | F31: Yes | J31: Yes | K31: Wave 2 — parameter variant of TC_ADM_USR_009: password "alllowercase1" (no-uppercase-required regression). Same page object/component; implement as an added data row, not new code. | N31: =IF(OR(H31="",L31=""),"",IF(AND(H31=F31,L31=J31),"Yes","No"))
A32: TC_ADM_USR_012 | B32: User Management > Users | C32: Confirm Password mismatch is rejected | D32: Validation | E32: P1 | F32: Yes | J32: Yes | K32: Wave 2 — reuses TC_ADM_USR_003's Add User form fixture; adds the Confirm-Password-mismatch assertion. Not a pure data variant. | N32: =IF(OR(H32="",L32=""),"",IF(AND(H32=F32,L32=J32),"Yes","No"))
A33: TC_ADM_USR_013 | B33: User Management > Users | C33: Search filter "Username" = "Admin" returns a consistent result set | D33: Functional | E33: P1 | F33: Yes | J33: Yes | N33: =IF(OR(H33="",L33=""),"",IF(AND(H33=F33,L33=J33),"Yes","No"))
A34: TC_ADM_USR_014 | B34: User Management > Users | C34: Search filter "User Role" = "ESS" returns a consistent result set | D34: Functional | E34: P1 | F34: Yes | J34: Yes | K34: Wave 2 — parameter variant of TC_ADM_USR_013: User Role = ESS filter. Same page object/component; implement as an added data row, not new code. | N34: =IF(OR(H34="",L34=""),"",IF(AND(H34=F34,L34=J34),"Yes","No"))
A35: TC_ADM_USR_015 | B35: User Management > Users | C35: Search filter "Status" = "Enabled" returns a consistent result set | D35: Functional | E35: P1 | F35: Yes | J35: Yes | K35: Wave 2 — parameter variant of TC_ADM_USR_013: Status = Enabled filter. Same page object/component; implement as an added data row, not new code. | N35: =IF(OR(H35="",L35=""),"",IF(AND(H35=F35,L35=J35),"Yes","No"))
A36: TC_ADM_USR_016 | B36: User Management > Users | C36: Search with no match shows the empty state | D36: Negative | E36: P2 | F36: Yes | J36: Yes | K36: Wave 2 — reuses TC_ADM_USR_013's search interaction; asserts the empty state instead of a filter match. Not a pure data variant. | N36: =IF(OR(H36="",L36=""),"",IF(AND(H36=F36,L36=J36),"Yes","No"))
A37: TC_ADM_USR_017 | B37: User Management > Users | C37: Reset clears all filters | D37: Functional | E37: P2 | F37: Yes | J37: Yes | K37: Wave 2 — reuses TC_ADM_USR_013's search fixture; adds the Reset-clears-filters assertion. Not a pure data variant. | N37: =IF(OR(H37="",L37=""),"",IF(AND(H37=F37,L37=J37),"Yes","No"))
A38: TC_ADM_USR_018 | B38: User Management > Users | C38: Edit a system user's role | D38: Functional | E38: P0 | F38: Yes | J38: Yes | N38: =IF(OR(H38="",L38=""),"",IF(AND(H38=F38,L38=J38),"Yes","No"))
A39: TC_ADM_USR_019 | B39: User Management > Users | C39: Password is optional on edit | D39: UI/UX | E39: P2 | F39: Yes | J39: Yes | K39: Wave 2 — reuses TC_ADM_USR_018's edit-flow fixture; adds the password-fields-hidden-until-toggled assertion. Not a pure data variant. | N39: =IF(OR(H39="",L39=""),"",IF(AND(H39=F39,L39=J39),"Yes","No"))
A40: TC_ADM_USR_020 | B40: User Management > Users | C40: Delete a single user with confirmation | D40: Functional | E40: P0 | F40: Yes | J40: Yes | N40: =IF(OR(H40="",L40=""),"",IF(AND(H40=F40,L40=J40),"Yes","No"))
...

Sheet Guidance
A1: Guidance — how to decide "valid in scope" and "needs automation"
A2: These two columns exist so a human can check whether the AI understood the requirements. The AI filled them first; the Review sheet shows its suggestion and reason next to a blank cell for yours. Use the criteria below so your calls stay consistent from row to row. Where you disagree, write why: disagreements are the useful output of this review.
A4: 1. How to fill the Review sheet
A5: Edit only the yellow cells in columns H, I, L and M. Pick Yes or No from each dropdown. A reason is required whenever you pick No. If you mark a case out of scope (H = No), mark it No for automation too (L = No): an out-of-scope case cannot be automated, and the sheet turns such a cell purple. The example below shows a filled row. It sits here, not on the Review sheet, so every Review answer stays yours.
A6: TC_ID | B6: MY_valid_in_scope | C6: MY_scope_reason | D6: MY_needs_automation | E6: MY_automation_reason
A7: TC_ADM_CFG_013 (example) | B7: No | C7: Disabling a module changes every logged-in user's sidebar at once on the shared demo. | D7: No | E7: Out of scope, so not automated.
A9: 2. When a case is OUT of scope (valid in scope = No)
A10: Ask: can this case be executed through the UI on this shared public demo, safely, and does the behaviour it tests actually exist on build 5.9? If any answer is no, the case is out of scope.
A11: Criterion | B11: Plain-language test | C11: What it looks like here | D11: Current AI "No" cases | E11: Note
A12: Blast radius | B12: Would running it change something for every other user of the demo at once? | C12: Publishing or resetting branding, toggling Modules, enabling LDAP. | D12: 3 | E12: Constitution VI.3: high-blast-radius screens default to observe-only.
A13: Blocked by a known defect | B13: Does a bug stop the steps from being carried out at all? | C13: A defect that makes a screen unusable, not one that gives a wrong result. | D13: 0 | E13: None today. BUG-001, BUG-002 and BUG-003 cases can all be executed; their tests assert the actual (wrong) behaviour as known-defect guards. A bug only makes a case out of scope if it prevents execution.
A14: Not present on build 5.9 | B14: Does the field, rule or control the case tests actually exist on this build? | C14: A format rule on a free-text field that has none; fields the spec describes but the screen does not show. | D14: 12 | E14: Decided from what M2 exploration observed, not from what the spec assumed.
A15: Outside UI scope | B15: Does checking the result need anything beyond the browser (email inbox, API, database)? | C15: Sending a real test email. | D15: 1 | E15: Constitution 1.3: email delivery, API and database checks are permanently out of scope.
A16: Unreachable with self-contained data | B16: Can the test create the state it needs with its own e2e_ records and a small footprint? | C16: Forcing a second page of users by creating 50+ accounts. | D16: 1 | E16: Not in your list, but it is the stated reason for one current case, so it is listed for consistency.
A18: 3. When a case is NOT worth automating (needs automation = No)
A19: Ask: would an automated check give a repeatable, deterministic yes/no answer that is worth the cost of maintaining it? Automate when the result is objective, the test can create and clean up its own data, and a regression would matter.
A20: Criterion | B20: Plain-language test | C20: What it looks like here | D20: Current in-scope AI "No" cases | E20: Note
A21: Visual judgement | B21: Does passing depend on a person judging how it looks? | C21: Branding previews, colour and layout appearance. | D21: 1 | E21: Counted together with colour pickers below; one case covers both.
A22: Colour pickers | B22: Is the main interaction a colour picker? | C22: Primary/Secondary/Font/Gradient colour fields on Corporate Branding. | D22: (see above) | E22: Also carries a global revert burden on the shared demo.
A23: File-dialog heavy | B23: Does the flow depend on OS file dialogs or many file fixtures? | C23: Attaching, replacing or deleting a Job Specification file; branding logo uploads. | D23: 0 | E23: No current case gives this as its reason, although 5 of them (JOB_010 to JOB_013, BRD_003) are upload flows. Their stated reason is "not observed before M3". Playwright can set files without a dialog, so this alone may not justify No.
A24: Non-deterministic | B24: Could the same steps give different results on different runs for reasons outside the test? | C24: Results that depend on other users' concurrent data, timing, or server hiccups. | D24: 0 | E24: No current case gives this as its reason. Flaky shared-demo behaviour is handled by the healing log, not by excluding cases.
A25: Expected result not yet observed | B25: Is the correct outcome known from observation, or only assumed from the spec? | C25: Duplicate-name wording, 51-character limits, validation messages never seen in M2. | D25: 44 | E25: The most common AI reason. See section 5: M4 has since observed all of these.
A26: Shared-state mutation | B26: Does it change instance-wide settings or shared structure that must be reverted exactly? | C26: Email subscriptions, Localization date format, Organization Structure nodes. | D26: 5 | E26: Automatable only with a guaranteed revert or dedicated seed data.
A28: 4. Worked examples — the 17 cases the AI marked out of scope
A29: TC_ID | B29: Sub_Module | C29: Title | D29: Category | E29: AI reason (verbatim from test_design.csv)
A30: TC_ADM_USR_023 | B30: User Management > Users | C30: Pagination integrity on the Users list | D30: Unreachable with self-contained data (would need 50+ owned records to force a second page) | E30: Exploration.md §2.1 recorded that every observation window on this screen showed ≤11 records — well under one page — and creating 50+ owned e2e_ users to force pagination would violate the self-contained/minimal-footprint spirit of Constitution Article VI. Pagination (BR-07) is instead exercised on Nationalities (see TC_ADM_NAT), the only Admin screen with enough records (exploration.md §2.1, §2.5).
A31: TC_ADM_JOB_005 | B31: Job Titles | C31: Job Title invalid format | D31: Not present on build 5.9 (no format rule exists for this free-text field) | E31: Field is free-form text with no format constraint distinct from its mandatory/length rules on this build; no separate format-specific validation was observed for this field during M2 (exploration.md §2), and none is applicable beyond the mandatory/duplicate/boundary cases already covered.
A32: TC_ADM_JOB_018 | B32: Pay Grades | C32: Name invalid format | D32: Not present on build 5.9 (no format rule exists for this free-text field) | E32: Field is free-form text with no format constraint distinct from its mandatory/length rules on this build; no separate format-specific validation was observed for this field during M2 (exploration.md §2), and none is applicable beyond the mandatory/duplicate/boundary cases already covered.
A33: TC_ADM_JOB_030 | B33: Employment Status | C33: Employment Status invalid format | D33: Not present on build 5.9 (no format rule exists for this free-text field) | E33: Field is free-form text with no format constraint distinct from its mandatory/length rules on this build; no separate format-specific validation was observed for this field during M2 (exploration.md §2), and none is applicable beyond the mandatory/duplicate/boundary cases already covered.
A34: TC_ADM_JOB_040 | B34: Job Categories | C34: Job Category invalid format | D34: Not present on build 5.9 (no format rule exists for this free-text field) | E34: Field is free-form text with no format constraint distinct from its mandatory/length rules on this build; no separate format-specific validation was observed for this field during M2 (exploration.md §2), and none is applicable beyond the mandatory/duplicate/boundary cases already covered.
A35: TC_ADM_ORG_010 | B35: Locations | C35: Name invalid format | D35: Not present on build 5.9 (no format rule exists for this free-text field) | E35: Field is free-form text with no format constraint distinct from its mandatory/length rules on this build; no separate format-specific validation was observed for this field during M2 (exploration.md §2), and none is applicable beyond the mandatory/duplicate/boundary cases already covered.
A36: TC_ADM_QUA_005 | B36: Skills | C36: Name invalid format | D36: Not present on build 5.9 (no format rule exists for this free-text field) | E36: Field is free-form text with no format constraint distinct from its mandatory/length rules on this build; no separate format-specific validation was observed for this field during M2 (exploration.md §2), and none is applicable beyond the mandatory/duplicate/boundary cases already covered.
A37: TC_ADM_QUA_015 | B37: Education | C37: Level invalid format | D37: Not present on build 5.9 (no format rule exists for this free-text field) | E37: Field is free-form text with no format constraint distinct from its mandatory/length rules on this build; no separate format-specific validation was observed for this field during M2 (exploration.md §2), and none is applicable beyond the mandatory/duplicate/boundary cases already covered.
A38: TC_ADM_QUA_024 | B38: Licenses | C38: Name invalid format | D38: Not present on build 5.9 (no format rule exists for this free-text field) | E38: Field is free-form text with no format constraint distinct from its mandatory/length rules on this build; no separate format-specific validation was observed for this field during M2 (exploration.md §2), and none is applicable beyond the mandatory/duplicate/boundary cases already covered.
A39: TC_ADM_QUA_033 | B39: Languages | C39: Name invalid format | D39: Not present on build 5.9 (no format rule exists for this free-text field) | E39: Field is free-form text with no format constraint distinct from its mandatory/length rules on this build; no separate format-specific validation was observed for this field during M2 (exploration.md §2), and none is applicable beyond the mandatory/duplicate/boundary cases already covered.
A40: TC_ADM_QUA_042 | B40: Memberships | C40: Name invalid format | D40: Not present on build 5.9 (no format rule exists for this free-text field) | E40: Field is free-form text with no format constraint distinct from its mandatory/length rules on this build; no separate format-specific validation was observed for this field during M2 (exploration.md §2), and none is applicable beyond the mandatory/duplicate/boundary cases already covered.
... A46: TC_ADM_CFG_019 | B46: LDAP Configuration | C46: Enable/Test Connection/Save are never exercised | D46: Blast radius on the shared demo (global change for every concurrent user) | E46: The screen carries its own on-page warning that incorrect configuration "may result in corrupted data" and recommends a database backup first; exploration.md §2.7/§9 explicitly states Enable, Test Connection, and Save were never clicked and this is "Not recommended for any mutation, ever, on this instance" — same blast-radius category as Configuration > Modules.
A48: 5. Evidence added after the AI made its suggestions (50 in-scope "not worth automating" cases)
A49: The AI set these values at M3. For 44 of these 50 cases its reason was that the behaviour had not been observed yet, so there was no verified expected result to assert. M4 then executed every in-scope case manually. All 50 of these were run: 49 passed and 1 failed (TC_ADM_JOB_004, which filed BUG-004). So for most of them, the evidence that reason was waiting for now exists. This is not a recommendation to change them. It is the information most likely to make your answer differ from the AI's.
A50: TC_ID | B50: Sub_Module | C50: Title | D50: AI reason category | E50: M4 manual result (agent_execution_report.html)
...

Sheet Summary
A1: Summary — AI suggestions vs. your decisions
A3: Test cases
A4: Total test cases | B4: =COUNTA(Review!$A$5:$A$207) -> 203 | C4: Rows on the Review sheet (matches test_design.csv).
A6: AI suggestions (from test_design.csv)
A7: valid in scope = Yes | B7: =COUNTIF(Review!$F$5:$F$207,"Yes") -> 186
A8: valid in scope = No | B8: =COUNTIF(Review!$F$5:$F$207,"No") -> 17
A9: needs automation = Yes | B9: =COUNTIF(Review!$J$5:$J$207,"Yes") -> 136
A10: needs automation = No | B10: =COUNTIF(Review!$J$5:$J$207,"No") -> 67
A12: Your decisions
A13: valid in scope: Yes / No / not yet filled
A14: Yes | B14: =COUNTIF(Review!$H$5:$H$207,"Yes") -> 0
A15: No | B15: =COUNTIF(Review!$H$5:$H$207,"No") -> 0
A16: not yet filled | B16: =B4-B14-B15 -> 203
A17: needs automation: Yes / No / not yet filled
A18: Yes | B18: =COUNTIF(Review!$L$5:$L$207,"Yes") -> 0
A19: No | B19: =COUNTIF(Review!$L$5:$L$207,"No") -> 0
A20: not yet filled | B20: =B4-B18-B19 -> 203
A21: Rows fully reviewed (both of your Yes/No cells set) | B21: =COUNTIF(Review!$N$5:$N$207,"Yes")+COUNTIF(Review!$N$5:$N$207,"No") -> 0
A23: Agreement
A24: Rows where you agree with the AI on both columns | B24: =COUNTIF(Review!$N$5:$N$207,"Yes") -> 0
A25: Rows where you disagree on at least one column | B25: =COUNTIF(Review!$N$5:$N$207,"No") -> 0
A26: AGREEMENT RATE | B26: =IF(B21=0,"Not yet filled in",B24/B21) -> Not yet filled in | C26: Placeholder until you fill the Review sheet: shows "Not yet filled in" until at least one row is fully reviewed, then agreed rows ÷ fully reviewed rows.
A27: valid in scope: rows where yours matches the AI | B27: =COUNTIFS(Review!$F$5:$F$207,"Yes",Review!$H$5:$H$207,"Yes")+COUNTIFS(Review!$F$5:$F$207,"No",Review!$H$5:$H$207,"No") -> 0
A28: valid in scope: agreement rate | B28: =IF(B14+B15=0,"Not yet filled in",B27/(B14+B15)) -> Not yet filled in
A29: needs automation: rows where yours matches the AI | B29: =COUNTIFS(Review!$J$5:$J$207,"Yes",Review!$L$5:$L$207,"Yes")+COUNTIFS(Review!$J$5:$J$207,"No",Review!$L$5:$L$207,"No") -> 0
A30: needs automation: agreement rate | B30: =IF(B18+B19=0,"Not yet filled in",B29/(B18+B19)) -> Not yet filled in
A32: Direction of disagreement
A33: Scope: AI said Yes, you said No | B33: =COUNTIFS(Review!$F$5:$F$207,"Yes",Review!$H$5:$H$207,"No") -> 0
A34: Scope: AI said No, you said Yes | B34: =COUNTIFS(Review!$F$5:$F$207,"No",Review!$H$5:$H$207,"Yes") -> 0
A35: Automation: AI said Yes, you said No | B35: =COUNTIFS(Review!$J$5:$J$207,"Yes",Review!$L$5:$L$207,"No") -> 0
A36: Automation: AI said No, you said Yes | B36: =COUNTIFS(Review!$J$5:$J$207,"No",Review!$L$5:$L$207,"Yes") -> 0
A38: Checks before handing the sheet back
A39: No without a reason (scope) | B39: =COUNTIFS(Review!$H$5:$H$207,"No",Review!$I$5:$I$207,"") -> 0 | C39: Should be 0. Every No needs a reason (CLAUDE.md §6).
A40: No without a reason (automation) | B40: =COUNTIFS(Review!$L$5:$L$207,"No",Review!$M$5:$M$207,"") -> 0 | C40: Should be 0.
A41: Out of scope but marked for automation | B41: =COUNTIFS(Review!$H$5:$H$207,"No",Review!$L$5:$L$207,"Yes") -> 0 | C41: Should be 0. An out-of-scope case cannot need automation.
