Workbook

Sheet Manual Execution
A1: Manual execution (M4) — all 186 valid-in-scope cases
A2: EVIDENCE POLICY: M4 required a screenshot for every failure and every defect ("evidence or it didn't happen", CLAUDE.md §8; M4 brief Rule 3). Passing cases with no defect did not need one. 6 of 186 cases cite screenshot files: both Fails (TC_ADM_NAV_004, TC_ADM_JOB_004), three defect cases whose own assertions passed (TC_ADM_NAT_010 / BUG-001, TC_ADM_BRD_001 / BUG-002, TC_ADM_CFG_001 / BUG-006), and TC_ADM_BRD_005 (colour-picker validation). Exception: TC_ADM_JOB_013 surfaced BUG-005 but no screenshot was taken, disclosed on the BUG-005 card. The two Blocked cases have none because nothing could be observed. Every other row states "Not required". deliverables/04-execution/evidence/ also holds 8 files no accepted result cites: 6 from the discarded first Branding/Configuration batch (timestamped 00:27–00:32 on 2026-09-24; that batch was not credited), 1 from the aborted concurrent attempt (STOPCONDITION-B1-shared-browser-session.png), and 1 extra shot from the accepted TC_ADM_BRD_005 run (TC_ADM_BRD_005-colorpicker-invalid.png). They are not attached to any row here. Status, Actual result, Bug id and Evidence come from the M4 report (deliverables/04-execution/agent_execution_report.html). Bug id lists every bug whose M4 card names the case. Steps and Expected come from the current test_design.csv; "Expected corrected after M4?" shows which 10 Expected cells changed after M4 and why, verified by diffing against a post-M4 snapshot of the Wave 1 rows (2026-09-24) and against git history. No snapshot exists for non-Wave-1 rows between M4 and the first commit (2026-09-25); none of them carries a correction marker.
A3: TC_ID | B3: Story_ID | C3: Sub_Module | D3: Title | E3: Priority | F3: Type | G3: Steps | H3: Expected | I3: Expected corrected after M4? | J3: Actual result | K3: Status (Pass/Fail/Blocked) | L3: Bug id | M3: Evidence file
A4: TC_ADM_NAV_001 | B4: US-00-01 | C4: Login | D4: Successful login routes to Dashboard | E4: P0 | F4: Functional | G4: 1. Enter username "Admin" 2. Enter password "admin123" 3. Click "Login" | H4: User is routed to the Dashboard; the top bar shows the logged-in user's name. | I4: No | J4: Logged out via topbar dropdown first to establish a genuinely unauthenticated state, then entered Admin/admin123 and clicked Login. Routed to `/web/index.php/dashboard/index`; topbar shows "manda user" (the account's linked employee display name — expected per environment note). | K4: Pass | M4: Not required: the case passed and raised no defect. M4 required screenshots only where a failure or defect needed evidence (6 of 186 cases have files).
A5: TC_ADM_NAV_002 | B5: US-00-01 | C5: Login | D5: Invalid credentials rejected without leaking which field is wrong (Admin/wrongPass) | E5: P0 | F5: Negative | G5: 1. Enter username "Admin" 2. Enter password "wrongPass" 3. Click "Login" | H5: Alert "Invalid credentials" is displayed; user remains on the login page. | I5: No | J5: Entered Admin/wrongPass, clicked Login. Alert box appeared with text "Invalid credentials" (verbatim); remained on `/web/index.php/auth/login`. | K5: Pass | M5: Not required: the case passed and raised no defect. M4 required screenshots only where a failure or defect needed evidence (6 of 186 cases have files).
A6: TC_ADM_NAV_003 | B6: US-00-01 | C6: Login | D6: Invalid credentials rejected without leaking which field is wrong (ghost/admin123) | E6: P0 | F6: Negative | G6: 1. Enter username "ghost" 2. Enter password "admin123" 3. Click "Login" | H6: Alert "Invalid credentials" is displayed; user remains on the login page. | I6: No | J6: Entered ghost/admin123, clicked Login. Alert "Invalid credentials" (verbatim) shown; remained on login page. | K6: Pass | M6: Not required: the case passed and raised no defect. M4 required screenshots only where a failure or defect needed evidence (6 of 186 cases have files).
A7: TC_ADM_NAV_004 | B7: US-00-01 | C7: Login | D7: Invalid credentials rejected without leaking which field is wrong (ADMIN/admin123) — KNOWN DEFECT: BUG-003 | E7: P0 | F7: Negative | G7: 1. Enter username "ADMIN" 2. Enter password "admin123" 3. Click "Login" | H7: ACTUAL (defective) product behaviour, per exploration.md §5 Bug Register (BUG-003, reproduced 1/1, deterministic case-insensitive DB lookup): no "Invalid credentials" alert is shown; the browser navigates to /web/index.php/dashboard/index, fully authenticated as the Admin account, despite the username case mismatch. This is the product's ACTUAL behaviour, not the desired exact-match-rejection behaviour — DO NOT assert "Invalid credentials" here. M5 asserts this directly (not test.fixme()), same treatment as TC_ADM_NAT_010/BUG-001 and TC_ADM_BRD_001/BUG-002. | I7: Yes: BUG-003. Rewritten on 2026-09-26 to assert the actual (defective) behaviour when the case moved to Wave 1 (commit c81f972). M4 ran it against "Invalid credentials". | J7: Entered ADMIN/admin123 (uppercase username), clicked Login. Expected: rejected with "Invalid credentials", remain on login page. Actual: login **succeeded** — routed to `/web/index.php/dashboard/index`, topbar shows "manda user". See **NEWBUG-B1R-1**. | K7: Fail | L7: BUG-003 | M7: TC_ADM_NAV_004-uppercase-username-login-succeeds.png
A8: TC_ADM_NAV_005 | B8: US-00-01 | C8: Login | D8: Required-field validation — Username left empty | E8: P1 | F8: Validation | G8: 1. Leave "Username" empty 2. Fill the other field 3. Submit | H8: Message "Required" is shown under "Username". | I8: No | J8: Left Username empty, filled Password=admin123, clicked Login. Field-adjacent message "Required" (verbatim) appeared under Username. | K8: Pass | M8: Not required: the case passed and raised no defect. M4 required screenshots only where a failure or defect needed evidence (6 of 186 cases have files).
A9: TC_ADM_NAV_006 | B9: US-00-01 | C9: Login | D9: Required-field validation — Password left empty | E9: P1 | F9: Validation | G9: 1. Leave "Password" empty 2. Fill the other field 3. Submit | H9: Message "Required" is shown under "Password". | I9: No | J9: Filled Username=Admin, left Password empty, clicked Login. Field-adjacent message "Required" (verbatim) appeared under Password. | K9: Pass | M9: Not required: the case passed and raised no defect. M4 required screenshots only where a failure or defect needed evidence (6 of 186 cases have files).
A10: TC_ADM_NAV_007 | B10: US-00-01 | C10: Login | D10: Deep link while unauthenticated redirects to login | E10: P0 | F10: Negative | G10: 1. Navigate directly to "/web/index.php/admin/viewSystemUsers" | H10: User is redirected to the login page. | I10: No | J10: While unauthenticated, navigated directly to `/web/index.php/admin/viewSystemUsers`. Browser was redirected to `/web/index.php/auth/login`. Re-verified independently in this batch per instructions (not inherited from any prior run's provisional result). | K10: Pass | M10: Not required: the case passed and raised no defect. M4 required screenshots only where a failure or defect needed evidence (6 of 186 cases have files).
A11: TC_ADM_NAV_008 | B11: US-00-02 | C11: Admin sidebar | D11: Admin top-tab "User Management" navigates to "System Users" | E11: P2 | F11: Navigation | G11: 1. Open the "User Management" tab | H11: "System Users" screen is displayed; breadcrumb reads two segments, "Admin" / "User Management" (verbatim, live-observed 2026-09-25 — not a single "Admin" segment as originally written). | I11: Yes: M5 live observation (2026-09-25). The breadcrumb has two segments, "Admin" / "User Management". Source: 05-automation/PROGRESS.md, NAV entry. | J11: Logged in as Admin/admin123; landed on Admin > User Management by default. Heading "System Users" displayed; breadcrumb reads "Admin" / "/ User Management". | K11: Pass | M11: Not required: the case passed and raised no defect. M4 required screenshots only where a failure or defect needed evidence (6 of 186 cases have files).
A12: TC_ADM_NAV_009 | B12: US-00-02 | C12: Admin sidebar | D12: Admin top-tab "Job" navigates to "Job Titles" | E12: P2 | F12: Navigation | G12: 1. Open the "Job" tab | H12: "Job Titles" screen is displayed; breadcrumb reads "Admin". | I12: No | J12: Opened "Job" tab, clicked "Job Titles" submenu item. URL `/admin/viewJobTitleList`; heading "Job Titles" displayed; breadcrumb "Admin" / "/ Job". | K12: Pass | M12: Not required: the case passed and raised no defect. M4 required screenshots only where a failure or defect needed evidence (6 of 186 cases have files).
A13: TC_ADM_NAV_010 | B13: US-00-02 | C13: Admin sidebar | D13: Admin top-tab "Organization" navigates to "General Information" | E13: P2 | F13: Navigation | G13: 1. Open the "Organization" tab | H13: "General Information" screen is displayed; breadcrumb reads "Admin". | I13: No | J13: Opened "Organization" tab, clicked "General Information". URL `/admin/viewOrganizationGeneralInformation`; heading "General Information"; breadcrumb "Admin" / "/ Organization". | K13: Pass | M13: Not required: the case passed and raised no defect. M4 required screenshots only where a failure or defect needed evidence (6 of 186 cases have files).
A14: TC_ADM_NAV_011 | B14: US-00-02 | C14: Admin sidebar | D14: Admin top-tab "Qualifications" navigates to "Skills" | E14: P2 | F14: Navigation | G14: 1. Open the "Qualifications" tab | H14: "Skills" screen is displayed; breadcrumb reads "Admin". | I14: No | J14: Opened "Qualifications" tab, clicked "Skills". URL `/admin/viewSkills`; heading "Skills" ((21) Records Found); breadcrumb "Admin" / "/ Qualifications". | K14: Pass | M14: Not required: the case passed and raised no defect. M4 required screenshots only where a failure or defect needed evidence (6 of 186 cases have files).
A15: TC_ADM_NAV_012 | B15: US-00-02 | C15: Admin sidebar | D15: Admin top-tab "Nationalities" navigates to "Nationalities" | E15: P2 | F15: Navigation | G15: 1. Open the "Nationalities" tab | H15: "Nationalities" screen is displayed; breadcrumb reads "Admin". | I15: No | J15: Clicked "Nationalities" top-tab link directly. URL `/admin/nationality`; heading "Nationalities" ((193) Records Found). Breadcrumb showed only a single heading "Admin", with **no** "/ Nationalities" second-level crumb (unlike every submenu-based tab tested, which showed "Admin" + "/ <Tab>"). Expected result only requires "breadcrumb reads Admin", which is literally satisfied, so marked Pass — logged as **OQ-B1R-1**. | K15: Pass | M15: Not required: the case passed and raised no defect. M4 required screenshots only where a failure or defect needed evidence (6 of 186 cases have files).
A16: TC_ADM_NAV_013 | B16: US-00-02 | C16: Admin sidebar | D16: Admin top-tab "Corporate Branding" navigates to "Corporate Branding" | E16: P2 | F16: Navigation | G16: 1. Open the "Corporate Branding" tab | H16: "Corporate Branding" screen is displayed; breadcrumb reads "Admin". | I16: No | J16: Clicked "Corporate Branding" top-tab link directly. URL `/admin/addTheme`; heading "Corporate Branding" displayed; breadcrumb single heading "Admin" only (same no-sub-crumb pattern as Nationalities — both are direct top-tab links rather than tabs-with-submenus). | K16: Pass | M16: Not required: the case passed and raised no defect. M4 required screenshots only where a failure or defect needed evidence (6 of 186 cases have files).
A17: TC_ADM_NAV_014 | B17: US-00-02 | C17: Admin sidebar | D17: Admin top-tab "Configuration" navigates to "Email Configuration" | E17: P2 | F17: Navigation | G17: 1. Open the "Configuration" tab | H17: "Email Configuration" screen is displayed; breadcrumb reads "Admin". | I17: No | J17: Opened "Configuration" tab, clicked "Email Configuration". URL `/admin/listMailConfiguration`; page shows "Email Configuration" label; breadcrumb "Admin" / "/ Configuration". | K17: Pass | M17: Not required: the case passed and raised no defect. M4 required screenshots only where a failure or defect needed evidence (6 of 186 cases have files).
A18: TC_ADM_NAV_015 | B18: US-00-03 | C18: Session | D18: Logout invalidates the session | E18: P0 | F18: Functional | G18: 1. Open the top-bar user dropdown 2. Click "Logout" | H18: User is returned to the login page; session is invalidated. | I18: No | J18: Opened topbar "manda user" dropdown, clicked "Logout". Redirected to `/web/index.php/auth/login`. | K18: Pass | M18: Not required: the case passed and raised no defect. M4 required screenshots only where a failure or defect needed evidence (6 of 186 cases have files).
A19: TC_ADM_NAV_016 | B19: US-00-03 | C19: Session | D19: Back-navigation after logout does not expose authenticated screens | E19: P0 | F19: Negative | G19: 1. Use the browser Back button to return to a previously-visited authenticated Admin URL | H19: The authenticated screen is not exposed; user is redirected to the login page. | I19: No | J19: Immediately after logout (previous case), pressed browser Back. The navigation event momentarily reported the prior authenticated URL (`/admin/listMailConfiguration`), but the rendered page (confirmed via a follow-up snapshot) was the Login form at `/web/index.php/auth/login` — the authenticated screen was not exposed. | K19: Pass | M19: Not required: the case passed and raised no defect. M4 required screenshots only where a failure or defect needed evidence (6 of 186 cases have files).
... A46: TC_ADM_JOB_003 | B46: US-02-01 | C46: Job Titles | D46: Duplicate Job Title is rejected | E46: P1 | F46: Negative | G46: 1. Click "Add" 2. Enter "Job Title" matching an existing record 3. Click "Save" | H46: Not directly exercised on this screen during M2. | I46: No | J46: On same Add form, typed Job Title = `Account Assistant` (existing record), clicked Save. Textbox showed inline error `Already exists` (verbatim). No record created, stayed on Add form. | K46: Pass | M46: Not required: the case passed and raised no defect. M4 required screenshots only where a failure or defect needed evidence (6 of 186 cases have files).
A47: TC_ADM_JOB_004 | B47: US-02-01 | C47: Job Titles | D47: Job Title boundary length (51 characters) | E47: P2 | F47: Boundary | G47: 1. Click "Add" 2. Enter a 51-character "Job Title" 3. Click "Save" | H47: The input is truncated at its maximum, or an explicit length error is displayed (exact outcome not yet resolved — see automation_reason). | I47: No | J47: Entered a 51-character Job Title (`e2e_m4b2r_00000000000000000000000000000000000000000`), clicked Save. Toast `Successfully Saved` appeared (no truncation error, no length-validation error of any kind). Reloaded the list and located the record: full 51-character value persisted verbatim, byte-for-byte, not truncated. Neither hypothesized outcome (truncation or explicit length error) occurred. | K47: Fail | L47: BUG-004 | M47: TC_ADM_JOB_004-51char-no-truncation.png
A48: TC_ADM_JOB_006 | B48: US-02-01 | C48: Job Titles | D48: Edit an existing Job Titles record | E48: P1 | F48: Functional | G48: 1. Open the record for edit 2. Change "Job Title" 3. Click "Save" | H48: Success toast is displayed; the list reflects the changed value. | I48: No | J48: Opened record `e2e_m4b2r_jobtitle_20260923` (id 76) for edit via pencil icon, changed Job Title to `e2e_m4b2r_jobtitle_20260923_edited`, clicked Save. Toast `Successfully Updated` appeared. Reloaded list: new value present. | K48: Pass | M48: Not required: the case passed and raised no defect. M4 required screenshots only where a failure or defect needed evidence (6 of 186 cases have files).
A49: TC_ADM_JOB_007 | B49: US-02-01 | C49: Job Titles | D49: Cancel discards changes on Job Titles | E49: P2 | F49: Negative | G49: 1. Click "Add" 2. Fill "Job Title" 3. Click "Cancel" | H49: User returns to the list; no record is created (pattern confirmed on Users/Pay Grades, exploration.md §2.1/§2.2). | I49: No | J49: Clicked Add, typed Job Title = `e2e_m4b2r_cancel_20260923`, clicked Cancel. Browser returned to the Job Titles list URL. Record count still `(30) Records Found` (unchanged) — no record created. | K49: Pass | M49: Not required: the case passed and raised no defect. M4 required screenshots only where a failure or defect needed evidence (6 of 186 cases have files).
A50: TC_ADM_JOB_008 | B50: US-02-01 | C50: Job Titles | D50: Delete a Job Titles record with confirmation | E50: P1 | F50: Functional | G50: 1. Click the record's delete icon 2. Confirm with "Yes, Delete" | H50: A confirmation dialog "Are you Sure?" / "The selected record will be permanently deleted. Are you sure you want to continue?" with buttons "No, Cancel" / "Yes, Delete" (verbatim, exploration.md §2.1) appears; after confirming, a success toast reading "Successfully Deleted" (verbatim, observed live in M5 on 2026-09-26, exploration.md Addendum A; M2 did not capture delete-toast wording) is displayed, the record is gone from the list and the record count decrements by 1. | I50: Yes: M5 live observation (2026-09-26). Delete toast wording "Successfully Deleted" added. Source: exploration.md Addendum A. | J50: Clicked delete (trash) icon on `e2e_m4b2r_jobtitle_20260923_edited` row. Dialog appeared, verbatim: "Are you Sure?" / "The selected record will be permanently deleted. Are you sure you want to continue?" with "No, Cancel" / "Yes, Delete" buttons. Clicked "Yes, Delete". Toast "Successfully Deleted" appeared. Count went 30 -> 29; record no longer in list. | K50: Pass | M50: Not required: the case passed and raised no defect. M4 required screenshots only where a failure or defect needed evidence (6 of 186 cases have files).
A51: TC_ADM_JOB_009 | B51: US-02-01 | C51: Job Titles | D51: Cancelling delete preserves the Job Titles record | E51: P2 | F51: Negative | G51: 1. Click the record's delete icon 2. Click "No, Cancel" | H51: Dialog closes; the record still exists (pattern confirmed on Users, exploration.md §2.1). | I51: No | J51: Clicked delete (trash) icon on the 51-char record row (from TC_ADM_JOB_004), got same "Are you Sure?" dialog, clicked "No, Cancel". Dialog closed; count remained `(29) Records Found`; record still present in list afterward. | K51: Pass | M51: Not required: the case passed and raised no defect. M4 required screenshots only where a failure or defect needed evidence (6 of 186 cases have files).
A52: TC_ADM_JOB_010 | B52: US-02-01 | C52: Job Titles | D52: Attach a Job Specification file within the 1MB limit | E52: P2 | F52: Functional | G52: 1. Click "Add" 2. Enter Job Title "e2e_jobtitle_<ts>" 3. Attach a valid file under 1MB to Job Specification 4. Click "Save" | H52: N/A — not exercised in M2. | I52: No | J52: Clicked Add, entered Job Title `e2e_m4b2r_jobtitle_attach_20260923`, attached a small (~80 byte) `.txt` file (`e2e_m4b2r_jobspec_valid.txt`, well under 1MB) to Job Specification, clicked Save. Toast `Successfully Saved`. Reopened the record for edit: Job Specification section now shows the attached filename `e2e_m4b2r_jobspec_valid.txt` plus three radios `Keep Current` / `Delete Current` / `Replace Current` (Keep Current pre-selected) — confirms the attachment persisted server-side. | K52: Pass | M52: Not required: the case passed and raised no defect. M4 required screenshots only where a failure or defect needed evidence (6 of 186 cases have files).
A53: TC_ADM_JOB_011 | B53: US-02-01 | C53: Job Titles | D53: Attach an unsupported file type to Job Specification | E53: P2 | F53: Negative | G53: 1. Attach a non-accepted file type to Job Specification 2. Click "Save" | H53: N/A — not exercised in M2. | I53: No | J53: Clicked Add, entered Job Title `e2e_m4b2r_jobtitle_badfile_20260923`, attached an unsupported file type (`e2e_m4b2r_unsupported.exe`, plain text content, well under 1MB) to Job Specification. Inline error appeared immediately on file selection: `File type not allowed` (verbatim) under the field. Clicked Save anyway — form stayed on Add screen, error persisted, no record created (count stayed `(30)`). | K53: Pass | M53: Not required: the case passed and raised no defect. M4 required screenshots only where a failure or defect needed evidence (6 of 186 cases have files).
A54: TC_ADM_JOB_012 | B54: US-02-01 | C54: Job Titles | D54: Replace an existing Job Specification attachment | E54: P3 | F54: Functional | G54: 1. Open the record for edit 2. Attach a new file to Job Specification 3. Click "Save" | H54: N/A — not exercised in M2. | I54: No | J54: Opened record id 78 (from TC_ADM_JOB_010) for edit. Selected radio `Replace Current` (had to click the label text — the underlying `<input type=radio>` is not directly clickable, consistent with CLAUDE.md §5.2's checkbox-trap note applying to radios too). A new "Upload Job Specification" file field appeared; uploaded `e2e_m4b2r_jobspec_replacement.txt`. Clicked Save. Toast `Successfully Updated`. Reopened the record: Job Specification now shows filename `e2e_m4b2r_jobspec_replacement.txt` (the old `e2e_m4b2r_jobspec_valid.txt` is gone). | K54: Pass | M54: Not required: the case passed and raised no defect. M4 required screenshots only where a failure or defect needed evidence (6 of 186 cases have files).
A55: TC_ADM_JOB_013 | B55: US-02-01 | C55: Job Titles | D55: Delete an existing Job Specification attachment | E55: P3 | F55: Functional | G55: 1. Open the record for edit 2. Remove the Job Specification attachment 3. Click "Save" | H55: N/A — not exercised in M2. | I55: No | J55: On record id 78, selected radio `Delete Current`, clicked Save. Toast `Successfully Updated`. Navigating directly to `/admin/saveJobTitle/78` afterward produced a console 404 (`GET .../api/v2/admin/job-titles/78` -> 404) and a blank Job Title field. Re-opened the record via the list's edit icon instead (not the stale URL): the record's Job Title (`e2e_m4b2r_jobtitle_attach_20260923`) was intact, but its underlying id had silently changed from 78 to 79; Job Specification correctly showed "No file selected" (no filename, no radios) — attachment removal itself worked correctly. List record count unchanged at `(30)`, no duplicate created. | K55: Pass | L55: BUG-005 | M55: None captured: BUG-005 was found during this passing case, but no screenshot was taken. The M4 report's BUG-005 card discloses this gap.
A56: TC_ADM_JOB_014 | B56: US-02-02 | C56: Pay Grades | D56: Create a Pay Grades record | E56: P1 | F56: Functional | G56: 1. Click "Add" 2. Complete "Name" (and any other mandatory fields) with a unique value 3. Click "Save" | H56: Success toast "Successfully Saved" is displayed (verbatim toast pattern confirmed across full-battery screens, exploration.md §2.1/§2.2/§2.4/§2.5); the record appears in the list. | I56: No | J56: Navigated to Pay Grades (`(10) Records Found` on entry — see Environment Notes). Clicked Add, entered Name `e2e_m4b2r_paygrade_20260923`, clicked Save. Page navigated to `/admin/payGrade/26` (Edit Pay Grade form, Name field pre-filled, Currencies sub-table "No Records Found") — toast had already auto-dismissed by the time of inspection, but the record's presence was independently confirmed via the list. | K56: Pass | M56: Not required: the case passed and raised no defect. M4 required screenshots only where a failure or defect needed evidence (6 of 186 cases have files).
A57: TC_ADM_JOB_015 | B57: US-02-02 | C57: Pay Grades | D57: Mandatory validation — Name empty | E57: P1 | F57: Validation | G57: 1. Leave "Name" empty 2. Click "Save" | H57: "Required" is displayed under the field (verbatim pattern confirmed on Users/Job Titles/Skills/Nationalities, exploration.md §2); no record is created. | I57: No | J57: Clicked Add, left Name empty, clicked Save. `Required` shown under Name. No navigation (stayed on Add form). | K57: Pass | M57: Not required: the case passed and raised no defect. M4 required screenshots only where a failure or defect needed evidence (6 of 186 cases have files).
A58: TC_ADM_JOB_016 | B58: US-02-02 | C58: Pay Grades | D58: Duplicate Name is rejected | E58: P1 | F58: Negative | G58: 1. Click "Add" 2. Enter "Name" matching an existing record 3. Click "Save" | H58: Not directly exercised on this screen during M2. | I58: No | J58: On same Add form, typed Name = `Grade 1` (existing record), clicked Save. Inline error `Already exists` (verbatim). No record created. | K58: Pass | M58: Not required: the case passed and raised no defect. M4 required screenshots only where a failure or defect needed evidence (6 of 186 cases have files).
A59: TC_ADM_JOB_017 | B59: US-02-02 | C59: Pay Grades | D59: Name boundary length (51 characters) | E59: P2 | F59: Boundary | G59: 1. Click "Add" 2. Enter a 51-character "Name" 3. Click "Save" | H59: The input is truncated at its maximum, or an explicit length error is displayed (exact outcome not yet resolved — see automation_reason). | I59: No | J59: On same Add form, typed a 51-character Name (`e2e_m4b2r_00000000000000000000000000000000000000000`), clicked Save. Inline error `Should not exceed 50 characters` (verbatim) shown; Save blocked, no record created. | K59: Pass | M59: Not required: the case passed and raised no defect. M4 required screenshots only where a failure or defect needed evidence (6 of 186 cases have files).
A60: TC_ADM_JOB_019 | B60: US-02-02 | C60: Pay Grades | D60: Edit an existing Pay Grades record | E60: P1 | F60: Functional | G60: 1. Open the record for edit 2. Change "Name" 3. Click "Save" | H60: Success toast is displayed; the list reflects the changed value. | I60: No | J60: Opened record id 26 for edit, changed Name to `e2e_m4b2r_paygrade_20260923_edited`, clicked Save. Toast `Successfully Updated`. Reloaded list: new value present. | K60: Pass | M60: Not required: the case passed and raised no defect. M4 required screenshots only where a failure or defect needed evidence (6 of 186 cases have files).
A61: TC_ADM_JOB_020 | B61: US-02-02 | C61: Pay Grades | D61: Cancel discards changes on Pay Grades | E61: P2 | F61: Negative | G61: 1. Click "Add" 2. Fill "Name" 3. Click "Cancel" | H61: User returns to the list; no record is created (pattern confirmed on Users/Pay Grades, exploration.md §2.1/§2.2). | I61: No | J61: Clicked Add, typed Name = `e2e_m4b2r_cancel_paygrade_20260923`, clicked Cancel. Returned to Pay Grades list; that name is absent from the list — no record created. | K61: Pass | M61: Not required: the case passed and raised no defect. M4 required screenshots only where a failure or defect needed evidence (6 of 186 cases have files).
A62: TC_ADM_JOB_021 | B62: US-02-02 | C62: Pay Grades | D62: Delete a Pay Grades record with confirmation | E62: P1 | F62: Functional | G62: 1. Click the record's delete icon 2. Confirm with "Yes, Delete" | H62: A confirmation dialog "Are you Sure?" / "The selected record will be permanently deleted. Are you sure you want to continue?" with buttons "No, Cancel" / "Yes, Delete" (verbatim, exploration.md §2.1) appears; after confirming, the record is gone from the list and the record count decrements by 1. | I62: No | J62: Created a dedicated owned record `e2e_m4b2r_paygrade_del_20260923`, confirmed present in list, clicked its delete icon, dialog appeared ("Are you Sure?" / same verbatim text / "No, Cancel" / "Yes, Delete"), clicked "Yes, Delete". Toast `Successfully Deleted`. Record no longer found in list afterward. | K62: Pass | M62: Not required: the case passed and raised no defect. M4 required screenshots only where a failure or defect needed evidence (6 of 186 cases have files).
A63: TC_ADM_JOB_022 | B63: US-02-02 | C63: Pay Grades | D63: Cancelling delete preserves the Pay Grades record | E63: P2 | F63: Negative | G63: 1. Click the record's delete icon 2. Click "No, Cancel" | H63: Dialog closes; the record still exists (pattern confirmed on Users, exploration.md §2.1). | I63: No | J63: Created a dedicated owned record `e2e_m4b2r_paygrade_delcancel_20260923`, clicked its delete icon, same confirm dialog appeared, clicked "No, Cancel". Dialog closed; record still present in the list afterward. | K63: Pass | M63: Not required: the case passed and raised no defect. M4 required screenshots only where a failure or defect needed evidence (6 of 186 cases have files).
A64: TC_ADM_JOB_023 | B64: US-02-02 | C64: Pay Grades | D64: Currency Minimum Salary must not exceed Maximum Salary | E64: P1 | F64: Boundary | G64: 1. Open Currencies on the pay grade 2. Enter Minimum Salary "60000" 3. Enter Maximum Salary "50000" 4. Attempt to save | H64: Inline errors are shown simultaneously: "Should be lower than Maximum Salary" under Minimum, "Should be higher than Minimum Salary" under Maximum (verbatim, exploration.md §2.2). | I64: No | J64: On record id 26 (`e2e_m4b2r_paygrade_20260923_edited`), clicked Currencies "Add", selected Currency `EUR - Euro`, entered Minimum Salary `60000`, Maximum Salary `50000`, clicked Save. Both inline errors appeared simultaneously, verbatim: `Should be lower than Maximum Salary` under Minimum, `Should be higher than Minimum Salary` under Maximum. Currencies sub-table remained "No Records Found" — no row created. | K64: Pass | M64: Not required: the case passed and raised no defect. M4 required screenshots only where a failure or defect needed evidence (6 of 186 cases have files).
A65: TC_ADM_JOB_024 | B65: US-02-02 | C65: Pay Grades | D65: Duplicate currency on the same Pay Grade is rejected | E65: P2 | F65: Negative | G65: 1. Attempt to add the same currency a second time 2. Click "Save" | H65: N/A — not exercised in M2. | I65: No | J65: On record id 26 (which already has Euro assigned from TC_ADM_JOB_023/025), clicked Currencies "Add" again and opened the Currency dropdown. Inspected the full ~150-option listbox: `EUR - Euro` is absent from the list entirely (options jump `ECS - Ecuador Sucre` -> `EEK - Estonian Krona` -> `EGP - Egyptian Pound` -> `ETB - Ethiopian Birr` -> `FJD - Fiji Dollar`, no EUR entry). | K65: Pass | M65: Not required: the case passed and raised no defect. M4 required screenshots only where a failure or defect needed evidence (6 of 186 cases have files).
A66: TC_ADM_JOB_025 | B66: US-02-02 | C66: Pay Grades | D66: Currency dropdown resolves by exact text among ~150 options | E66: P2 | F66: Functional | G66: 1. Open the Currency dropdown 2. Select an option by its exact visible text (e.g. "EUR - Euro") | H66: The selected currency's exact text is reflected in the trigger; no other similarly-named currency is matched (locator risk register, exploration.md §6). | I66: No | J66: On the same open Add-Currency form, the Currency dropdown was opened and `EUR - Euro` selected by its exact visible text among the full ~150-option list (confirmed via listbox snapshot showing neighboring options `EGP`, `ETB`, `EUR`, `FJD`, `FKP`, `GBP` etc. — no similarly-named currency was matched instead). The trigger correctly displayed `EUR - Euro` after selection. Corrected Min/Max to `30000`/`60000` and saved: toast `Successfully Saved`; Currencies table now shows `(1) Record Found` with row `Euro / 30,000.00 / 60,000.00` — confirms the selected currency (not a neighboring one) was the one actually persisted. | K66: Pass | M66: Not required: the case passed and raised no defect. M4 required screenshots only where a failure or defect needed evidence (6 of 186 cases have files).
...

Sheet Automation
A1: Automation — the 52 Wave 1 automated cases
A2: Last result, Duration and Retries come from the latest full-suite run, retained on disk at deliverables/05-automation/runs/2026-09-26_full-suite/ (playwright-run.json; started 2026-09-26T16:28:27.084Z, one worker, retries configured at 1). "Pass (flaky)" means the test failed its first attempt and passed on the automatic retry; both are diagnosed as environment instability in healing_process.md (HEAL-028, HEAL-029). Duration is the final attempt's. "Asserts a known defect" = the CSV row carries a Linked_Bug and the test asserts the product's actual (defective) behaviour.
A3: Automation_ID | B3: TC_ID | C3: Story_ID | D3: Sub_Module | E3: Title | F3: Priority | G3: Spec file | H3: Test title | I3: Last result | J3: Duration (s) | K3: Retries | L3: Asserts a known defect (y/n)
A4: TC_ADM_NAV_001 | B4: TC_ADM_NAV_001 | C4: US-00-01 | D4: Login | E4: Successful login routes to Dashboard | F4: P0 | G4: tests/admin/nav.spec.ts | H4: TC_ADM_NAV_001 - successful login routes to Dashboard | I4: Pass | J4: 5.9 | K4: 0 | L4: n
A5: TC_ADM_NAV_002 | B5: TC_ADM_NAV_002 | C5: US-00-01 | D5: Login | E5: Invalid credentials rejected without leaking which field is wrong (Admin/wrongPass) | F5: P0 | G5: tests/admin/nav.spec.ts | H5: TC_ADM_NAV_002 - invalid credentials rejected without leaking which field is wrong | I5: Pass | J5: 4.7 | K5: 0 | L5: n
A6: TC_ADM_NAV_003 | B6: TC_ADM_NAV_003 | C6: US-00-01 | D6: Login | E6: Invalid credentials rejected without leaking which field is wrong (ghost/admin123) | F6: P0 | G6: tests/admin/nav.spec.ts | H6: TC_ADM_NAV_003 - invalid credentials rejected without leaking which field is wrong (nonexistent username) | I6: Pass | J6: 5.6 | K6: 0 | L6: n
A7: TC_ADM_NAV_004 | B7: TC_ADM_NAV_004 | C7: US-00-01 | D7: Login | E7: Invalid credentials rejected without leaking which field is wrong (ADMIN/admin123) — KNOWN DEFECT: BUG-003 | F7: P0 | G7: tests/admin/nav.spec.ts | H7: TC_ADM_NAV_004 - invalid credentials rejected without leaking which field is wrong (uppercase username) — KNOWN DEFECT BUG-003 | I7: Pass | J7: 4.9 | K7: 0 | L7: y (BUG-003)
A8: TC_ADM_NAV_005 | B8: TC_ADM_NAV_005 | C8: US-00-01 | D8: Login | E8: Required-field validation — Username left empty | F8: P1 | G8: tests/admin/nav.spec.ts | H8: TC_ADM_NAV_005 - required-field validation, Username left empty | I8: Pass | J8: 2.9 | K8: 0 | L8: n
A9: TC_ADM_NAV_007 | B9: TC_ADM_NAV_007 | C9: US-00-01 | D9: Login | E9: Deep link while unauthenticated redirects to login | F9: P0 | G9: tests/admin/nav.spec.ts | H9: TC_ADM_NAV_007 - deep link while unauthenticated redirects to login | I9: Pass | J9: 3.3 | K9: 0 | L9: n
A10: TC_ADM_NAV_008 | B10: TC_ADM_NAV_008 | C10: US-00-02 | D10: Admin sidebar | E10: Admin top-tab "User Management" navigates to "System Users" | F10: P2 | G10: tests/admin/nav.spec.ts | H10: TC_ADM_NAV_008 - Admin top-tab "User Management" navigates to System Users | I10: Pass | J10: 6.4 | K10: 0 | L10: n
A11: TC_ADM_NAV_015 | B11: TC_ADM_NAV_015 | C11: US-00-03 | D11: Session | E11: Logout invalidates the session | F11: P0 | G11: tests/admin/nav.spec.ts | H11: TC_ADM_NAV_015 - logout invalidates the session | I11: Pass | J11: 8.7 | K11: 0 | L11: n
A12: TC_ADM_NAV_016 | B12: TC_ADM_NAV_016 | C12: US-00-03 | D12: Session | E12: Back-navigation after logout does not expose authenticated screens | F12: P0 | G12: tests/admin/nav.spec.ts | H12: TC_ADM_NAV_016 - back-navigation after logout does not expose authenticated screens | I12: Pass | J12: 16.2 | K12: 0 | L12: n
A13: TC_ADM_USR_001 | B13: TC_ADM_USR_001 | C13: US-01-02 | D13: User Management > Users | E13: Add a valid ESS user | F13: P0 | G13: tests/admin/usr.spec.ts | H13: TC_ADM_USR_001 - add a valid ESS system user | I13: Pass (flaky) | J13: 30.1 | K13: 1 | L13: n
A14: TC_ADM_USR_002 | B14: TC_ADM_USR_002 | C14: US-01-02 | D14: User Management > Users | E14: Username uniqueness is enforced | F14: P0 | G14: tests/admin/usr.spec.ts | H14: TC_ADM_USR_002 - username uniqueness is enforced | I14: Pass | J14: 20.9 | K14: 0 | L14: n
A15: TC_ADM_USR_003 | B15: TC_ADM_USR_003 | C15: US-01-02 | D15: User Management > Users | E15: Mandatory field blocks submission — User Role empty | F15: P0 | G15: tests/admin/usr.spec.ts | H15: TC_ADM_USR_003 - mandatory field blocks submission when User Role is empty | I15: Pass | J15: 11.8 | K15: 0 | L15: n
... A55: TC_ADM_CFG_011 | B55: TC_ADM_CFG_011 | C55: US-07-05 | D55: Modules | E55: Admin and Pim modules are locked enabled (checked and disabled) | F55: P2 | G55: tests/admin/cfg.spec.ts | H55: TC_ADM_CFG_011 - Admin and Pim modules are locked enabled (checked and disabled) | I55: Pass | J55: 6.4 | K55: 0 | L55: n

Sheet Comparison
A1: Comparison — from designed to automated
A2: Counts whose Source says "Formula" are computed from the Manual Execution and Automation sheets, as a cross-check. The others are counted from test_design.csv (203 rows) and stated as values, since the full catalogue is not reproduced in this workbook. Every drop names its reason and count.
A4: Stage | B4: Count | C4: Drop from previous stage | D4: Reason for the drop | E4: Source
A5: Designed | B5: 203 | D5: Every test case in the M3 catalogue, covering all 34 Admin user stories. | E5: test_design.csv (203 rows)
A6: Valid in scope | B6: 186 | C6: =B5-B6 -> 17 | D6: 17 cases marked out of scope: 12 test behaviour not present on build 5.9 (11 "invalid format" cases for free-text fields with no format rule, and 1 whose fields were never observed on the screen); 3 have global blast radius on the shared demo (publishing/resetting branding, toggling Modules, enabling LDAP); 1 is outside UI scope (sends a real email); 1 is unreachable with self-contained data (would need 50+ owned users to force a second page). | E6: test_design.csv "valid in scope" and scope_reason
A7: Executed manually | B7: =COUNTA('Manual Execution'!$A$4:$A$189) -> 186 | C7: =B6-B7 -> 0 | D7: ="No drop: every in-scope case was executed in M4. "&COUNTIF('Manual Execution'!$K$4:$K$189,"Pass")&" Pass, "&COUNTIF('Manual Execution'!$K$4:$K$189,"Fail")&" Fail (TC_ADM_NAV_004 → BUG-003, TC_ADM_JOB_004 → BUG-004), "&COUNTIF('Manual Execution'!$K$4:$K$189,"Blocked")&" Blocked (TC_ADM_CFG_003/004: a tool permission check denied the Save click; accepted as an environment constraint). Blocked cases count as executed, as in the M4 report." -> No drop: every in-scope case was executed in M4. 182 Pass, 2 Fail (TC_ADM_NAV_004 → BUG-003, TC_ADM_JOB_004 → BUG-004), 2 Blocked (TC_ADM_CFG_003/004: a tool permission check denied the Save click; accepted as an environment constraint). Blocked cases count as executed, as in the M4 report. | E7: Formula: count of rows on the Manual Execution sheet (from agent_execution_report.html, M4)
A8: Marked for automation | B8: 136 | C8: =B7-B8 -> 50 | D8: 50 in-scope cases marked not worth automating at M3: 44 because the expected result had not yet been observed (Constitution V.3), 5 because they mutate shared state and need a guaranteed revert or seed data, 1 because it depends on visual judgement (colour picker). M4 later executed all 50: 49 passed and 1 failed, so these suggestions are now under human review (deliverables/03-test-design/scope_review.xlsx). | E8: test_design.csv "needs automation" and automation_reason; M4 results
A9: Automated (Wave 1) | B9: =COUNTA(Automation!$A$4:$A$55) -> 52 | C9: =B8-B9 -> 84 | D9: 84 cases not yet automated: sequenced into Wave 2 for capacity. A full run takes roughly 40–60 minutes and Gate G5 requires 3 consecutive green runs after every healing cycle, so all 136 could not be built and verified in one cycle. Scheduled, not descoped. | E9: Formula: count of rows on the Automation sheet (test_design.csv automation_wave; test_design_coverage.md "Execution sequencing")
A10: Scheduled (Wave 2) | B10: 84 | C10: (remainder) | D10: Not a further drop: the other part of the 136 marked for automation. 63 are parameter variants of existing Wave 1 tests (75.0%), 17 reuse an existing component with a new page object or extra assertion, 4 are deferred standalone read-only checks. | E10: test_design.csv automation_wave and automation_reason
A12: Check: Automated + Scheduled = Marked for automation | B12: =IF(B9+B10=B8,"OK","MISMATCH") -> OK
A13: Check: Executed manually = Valid in scope | B13: =IF(B7=B6,"OK","MISMATCH") -> OK
A14: Latest run: passed on first attempt | B14: =COUNTIF(Automation!$I$4:$I$55,"Pass") -> 50
A15: Latest run: passed on retry (flaky) | B15: =COUNTIF(Automation!$I$4:$I$55,"Pass (flaky)") -> 2
A16: Latest run: failed | B16: =COUNTIF(Automation!$I$4:$I$55,"Fail") -> 0
A19: By sub-module
A20: Automation coverage % = Automated (Wave 1) ÷ Executed manually. Designed, Valid in scope and Marked for automation are counted from test_design.csv; Executed manually and Automated are formulas over the first two sheets.
A21: Sub-module | B21: Designed | C21: Valid in scope | D21: Executed manually | E21: Marked for automation | F21: Automated (Wave 1) | G21: Automation coverage %
A22: Login / Session / Navigation (NAV) | B22: 16 | C22: 16 | D22: =COUNTIF('Manual Execution'!$A$4:$A$189,"TC_ADM_NAV_*") -> 16 | E22: 16 | F22: =COUNTIF(Automation!$A$4:$A$55,"TC_ADM_NAV_*") -> 9 | G22: =IF(D22=0,0,F22/D22) -> 0.5625
A23: User Management (USR) | B23: 25 | C23: 24 | D23: =COUNTIF('Manual Execution'!$A$4:$A$189,"TC_ADM_USR_*") -> 24 | E23: 23 | F23: =COUNTIF(Automation!$A$4:$A$55,"TC_ADM_USR_*") -> 12 | G23: =IF(D23=0,0,F23/D23) -> 0.5
A24: Job (JOB) | B24: 55 | C24: 51 | D24: =COUNTIF('Manual Execution'!$A$4:$A$189,"TC_ADM_JOB_*") -> 51 | E24: 33 | F24: =COUNTIF(Automation!$A$4:$A$55,"TC_ADM_JOB_*") -> 8 | G24: =IF(D24=0,0,F24/D24) -> 0.15686275
A25: Organization (ORG) | B25: 22 | C25: 21 | D25: =COUNTIF('Manual Execution'!$A$4:$A$189,"TC_ADM_ORG_*") -> 21 | E25: 9 | F25: =COUNTIF(Automation!$A$4:$A$55,"TC_ADM_ORG_*") -> 4 | G25: =IF(D25=0,0,F25/D25) -> 0.19047619
A26: Qualifications (QUA) | B26: 47 | C26: 42 | D26: =COUNTIF('Manual Execution'!$A$4:$A$189,"TC_ADM_QUA_*") -> 42 | E26: 32 | F26: =COUNTIF(Automation!$A$4:$A$55,"TC_ADM_QUA_*") -> 7 | G26: =IF(D26=0,0,F26/D26) -> 0.16666667
A27: Nationalities (NAT) | B27: 11 | C27: 10 | D27: =COUNTIF('Manual Execution'!$A$4:$A$189,"TC_ADM_NAT_*") -> 10 | E27: 9 | F27: =COUNTIF(Automation!$A$4:$A$55,"TC_ADM_NAT_*") -> 5 | G27: =IF(D27=0,0,F27/D27) -> 0.5
A28: Corporate Branding (BRD) | B28: 7 | C28: 5 | D28: =COUNTIF('Manual Execution'!$A$4:$A$189,"TC_ADM_BRD_*") -> 5 | E28: 3 | F28: =COUNTIF(Automation!$A$4:$A$55,"TC_ADM_BRD_*") -> 3 | G28: =IF(D28=0,0,F28/D28) -> 0.6
A29: Configuration (CFG) | B29: 20 | C29: 17 | D29: =COUNTIF('Manual Execution'!$A$4:$A$189,"TC_ADM_CFG_*") -> 17 | E29: 11 | F29: =COUNTIF(Automation!$A$4:$A$55,"TC_ADM_CFG_*") -> 4 | G29: =IF(D29=0,0,F29/D29) -> 0.23529412
A30: Total | B30: =SUM(B22:B29) -> 203 | C30: =SUM(C22:C29) -> 186 | D30: =SUM(D22:D29) -> 186 | E30: =SUM(E22:E29) -> 136 | F30: =SUM(F22:F29) -> 52 | G30: =IF(D30=0,0,F30/D30) -> 0.27956989

Sheet Selection rationale
A1: Selection rationale — why these 52 were automated first
A2: Source: test_design_coverage.md, "Execution sequencing (Wave 1 / Wave 2)" (the original 47-case selection rule) and §8.5 (the rule that every P0 case is Wave 1, which added 5 cases on 2026-09-26). Counts below are computed from test_design.csv. A case can satisfy more than one rule.
A4: Rule | B4: Cases in Wave 1 | C4: What it means, and which cases
A5: 1. Every P0 case is Wave 1 | B5: 17 | C5: Unconditional since 2026-09-26 (test_design_coverage.md §8.5): promoting a case to P0 includes automating it. 17 of 17 P0 cases are in Wave 1. Cases: TC_ADM_NAV_001, TC_ADM_NAV_002, TC_ADM_NAV_003, TC_ADM_NAV_004, TC_ADM_NAV_007, TC_ADM_NAV_015, TC_ADM_NAV_016, TC_ADM_USR_001, TC_ADM_USR_002, TC_ADM_USR_003, TC_ADM_USR_005, TC_ADM_USR_006, TC_ADM_USR_007, TC_ADM_USR_018, TC_ADM_USR_020, TC_ADM_USR_022, TC_ADM_NAT_010.
A6: 2. One reference implementation per repeated CRUD family | B6: 13 | C6: The Job group (5 screens) and the Qualifications group (5 screens) share one CRUD contract. One screen per group was built as the real page object: Job Titles (TC_ADM_JOB_001, TC_ADM_JOB_002, TC_ADM_JOB_006, TC_ADM_JOB_007, TC_ADM_JOB_008, TC_ADM_JOB_009) and Skills (TC_ADM_QUA_001, TC_ADM_QUA_002, TC_ADM_QUA_006, TC_ADM_QUA_007, TC_ADM_QUA_008, TC_ADM_QUA_009, TC_ADM_QUA_010, the last being the long-description regression case). The sibling screens' equivalent cases are Wave 2 data rows against these page objects.
A7: … plus screen-specific logic | B7: 2 | C7: Logic that is not shared across a group stayed in Wave 1 regardless: TC_ADM_JOB_023 (Pay Grades currency Min/Max), TC_ADM_JOB_049 (Work Shift overnight rejection, which resolved OQ-02).
A8: 3. Known-defect guards | B8: 3 | C8: Every case carrying a Linked_Bug: TC_ADM_NAV_004 (BUG-003), TC_ADM_NAT_010 (BUG-001), TC_ADM_BRD_001 (BUG-002). Each asserts the product's actual defective behaviour so the test fails when the bug is fixed.
A9: 4. Happy paths, plus a negative and a boundary case per sub-module | B9: 19 | C9: Login and navigation happy paths, and at least one negative and one boundary case per sub-module where the in-scope set has one (NAV, ORG and USR have no boundary case to pick). Cases not already covered by rules 1–3: TC_ADM_NAV_005, TC_ADM_NAV_008, TC_ADM_USR_009, TC_ADM_USR_013, TC_ADM_USR_024, TC_ADM_ORG_001, TC_ADM_ORG_006, TC_ADM_ORG_007, TC_ADM_ORG_019, TC_ADM_NAT_001, TC_ADM_NAT_002, TC_ADM_NAT_003, TC_ADM_NAT_011, TC_ADM_BRD_002, TC_ADM_BRD_006, TC_ADM_CFG_001, TC_ADM_CFG_003, TC_ADM_CFG_008, TC_ADM_CFG_011.
A10: 5. Exclusion rule | B10: — | C10: Nothing M2 flagged as slow, fragile or upload-heavy was pulled into Wave 1 (the documented wording). Note: this is not the same as excluding everything non-deterministic. Shared-demo flakiness is handled by the healing process, not by selection: 4 environment-instability entries were diagnosed on Wave 1 tests (HEAL-022, 027, 028, 029).
A12: Wave 2: scheduled, not descoped
A13: All 84 Wave 2 cases remain "needs automation = Yes", each with an Automation_ID already assigned. The automation_wave column records only when a case is built, never whether. 63 of the 84 (75.0%) are parameter variants of existing Wave 1 tests: the same page object and interaction with different input data, so they are extra rows in a data-driven test rather than new code. A further 17 reuse an existing component (a new page object for a sibling screen, or an extra assertion on an existing fixture) and 4 are deferred standalone read-only checks with no Wave 1 sibling.
A14: About the percentage: the originally published figure was 76.4% (68 of 89), measured when the waves were first sequenced. On 2026-09-26 five of those parameter variants (TC_ADM_NAV_003, NAV_004, USR_005, USR_006, USR_007) moved to Wave 1 under the P0 rule, which leaves 63 of 84 = 75.0%. This workbook uses the current figure.
